# 2023-09-17 broken

- doh!

```text
shanes-mbp:workflow shanenull$ ./push.sh 
push local branch main to origin        git@github.com:shane0/workflow.git y n ?
y
On branch main
Your branch is up to date with 'origin/main'.

nothing to commit, working tree clean
Everything up-to-date
INFO     -  Cleaning site directory
INFO     -  Building documentation to directory: /Users/shanenull/workflow/site
Traceback (most recent call last):
  File "/Users/shanenull/.pyenv/versions/3.9.9/bin/mkdocs", line 8, in <module>
    sys.exit(cli())
  File "/Users/shanenull/.pyenv/versions/3.9.9/lib/python3.9/site-packages/click/core.py", line 1130, in __call__
    return self.main(*args, **kwargs)
  File "/Users/shanenull/.pyenv/versions/3.9.9/lib/python3.9/site-packages/click/core.py", line 1055, in main
    rv = self.invoke(ctx)
  File "/Users/shanenull/.pyenv/versions/3.9.9/lib/python3.9/site-packages/click/core.py", line 1657, in invoke
    return _process_result(sub_ctx.command.invoke(sub_ctx))
  File "/Users/shanenull/.pyenv/versions/3.9.9/lib/python3.9/site-packages/click/core.py", line 1404, in invoke
    return ctx.invoke(self.callback, **ctx.params)
  File "/Users/shanenull/.pyenv/versions/3.9.9/lib/python3.9/site-packages/click/core.py", line 760, in invoke
    return __callback(*args, **kwargs)
  File "/Users/shanenull/.pyenv/versions/3.9.9/lib/python3.9/site-packages/mkdocs/__main__.py", line 277, in gh_deploy_command
    build.build(cfg, dirty=not clean)
  File "/Users/shanenull/.pyenv/versions/3.9.9/lib/python3.9/site-packages/mkdocs/commands/build.py", line 320, in build
    _build_theme_template(template, env, files, config, nav)
  File "/Users/shanenull/.pyenv/versions/3.9.9/lib/python3.9/site-packages/mkdocs/commands/build.py", line 118, in _build_theme_template
    output = _build_template(template_name, template, files, config, nav)
  File "/Users/shanenull/.pyenv/versions/3.9.9/lib/python3.9/site-packages/mkdocs/commands/build.py", line 97, in _build_template
    output = template.render(context)
  File "/Users/shanenull/.pyenv/versions/3.9.9/lib/python3.9/site-packages/jinja2/environment.py", line 1301, in render
    self.environment.handle_exception()
  File "/Users/shanenull/.pyenv/versions/3.9.9/lib/python3.9/site-packages/jinja2/environment.py", line 936, in handle_exception
    raise rewrite_traceback_stack(source=source)
  File "/Users/shanenull/.pyenv/versions/3.9.9/lib/python3.9/site-packages/material/404.html", line 4, in top-level template code
    {% extends "main.html" %}
  File "/Users/shanenull/.pyenv/versions/3.9.9/lib/python3.9/site-packages/material/main.html", line 4, in top-level template code
    {% extends "base.html" %}
  File "/Users/shanenull/.pyenv/versions/3.9.9/lib/python3.9/site-packages/material/base.html", line 192, in top-level template code
    {% block footer %}
  File "/Users/shanenull/.pyenv/versions/3.9.9/lib/python3.9/site-packages/material/base.html", line 193, in block 'footer'
    {% include "partials/footer.html" %}
  File "/Users/shanenull/.pyenv/versions/3.9.9/lib/python3.9/site-packages/material/partials/footer.html", line 50, in top-level template code
    {% include "partials/social.html" %}
  File "/Users/shanenull/.pyenv/versions/3.9.9/lib/python3.9/site-packages/material/partials/social.html", line 8, in top-level template code
    {% set _, url = social.link.split("//") %}
ValueError: too many values to unpack (expected 2)
```
